Workbook

Sheet README
A1: Supplementary Tables S1 to S13
A3: • This workbook accompanies the final manuscript and contains complete result tables; it is not a reviewer-response document.
A4: • Evidence tiers are kept distinct: primary statistical models, internal sensitivity analyses, and descriptive molecular or tissue context.
A5: • SMR global corrections apply to the second-stage tests and do not calibrate the first-stage disease-GWAS-guided region selection.
A6: • The RPE multivariable finding is single-variant-dependent and estimator-sensitive. It is not presented as an established protective mechanism.
A7: • Visium analyses are descriptive because disease status is completely confounded with donor identity and matched random gene-set tests were null.
A8: • The GCL-TNXB mediation pipeline retains its historical 32-instrument input and is separate from the 33-instrument full54 forward model.
A9: • S6c records only the heritability values displayed in the retained Figure 2 graphic. It does not impute missing h2 standard errors.
A10: • All tables use three-line formatting: thick top and bottom rules, a thin header rule, and no vertical or internal horizontal rules.
A11: • Source IDs map to S13a_data_sources and to the reproducibility archive. The GitHub repository location is specified in the Availability of data and materials statement; no archived DOI has been assigned.

Sheet Table_Index
A1: Sheet | B1: Group | C1: Description | D1: Records | E1: Source
A2: S1_SMR_42pairs | B2: S1 | C2: Two-stage SMR candidate catalog with second-stage global-correction status. | D2: =COUNTA(S1_SMR_42pairs!A2:A43) -> 42 | E2: eQTLGen; disease GWAS
A3: S2_SMR_2354tests | B3: S2 | C3: All 2,354 disease-probe tests entering SMR Select with within-disease and second-stage global corrections. | D3: =COUNTA(S2_SMR_2354tests!A2:A2355) -> 2354 | E3: eQTLGen; disease GWAS
A4: S2b_SMR_rule_counts | B4: S2 | C4: Pair and unique-probe counts under each SMR correction and HEIDI rule. | D4: =COUNTA(S2b_SMR_rule_counts!A2:A7) -> 6 | E4: Derived results
A5: S3_forwardMR_full54 | B5: S3 | C5: Complete 54 forward MR models with five estimators, matched confidence intervals, FDR families, and input hashes. | D5: =COUNTA(S3_forwardMR_full54!A2:A55) -> 54 | E5: OCT; disease GWAS
A6: S4a_MR_PRESSO_54 | B6: S4 | C6: Unified 10,000-simulation MR-PRESSO results and formal outlier decisions. | D6: =COUNTA(S4a_MR_PRESSO_54!A2:A55) -> 54 | E6: Derived results
A7: S4b_MR_LOO_2045 | B7: S4 | C7: Leave-one-out estimates for all 54 forward models. | D7: =COUNTA(S4b_MR_LOO_2045!A2:A2046) -> 2045 | E7: Derived results
A8: S4c_singleSNP_2045 | B8: S4 | C8: Single-SNP Wald ratios for all forward instruments. | D8: =COUNTA(S4c_singleSNP_2045!A2:A2046) -> 2045 | E8: OCT; disease GWAS
A9: S4d_input_reconciliation | B9: S4 | C9: Reconciliation of current MR inputs with historical models; valid variants were retained. | D9: =COUNTA(S4d_input_reconciliation!A2:A55) -> 54 | E9: Derived results
A10: S4e_IAMDGC_audit | B10: S4 | C10: IAMDGC 2.0 extraction and exact historical-result reconciliation for nine models. | D10: =COUNTA(S4e_IAMDGC_audit!A2:A10) -> 9 | E10: IAMDGC 2.0
A11: S4f_FDR_families | B11: S4 | C11: Definitions and counts for the forward MR multiplicity families. | D11: =COUNTA(S4f_FDR_families!A2:A19) -> 18 | E11: Derived results
A12: S5_reverseMR_54 | B12: S5 | C12: Reverse MR estimates and diagnostics; the nine winkler_earlyamd rows form the primary reverse family. | D12: =COUNTA(S5_reverseMR_54!A2:A55) -> 54 | E12: OCT; disease GWAS
A13: S5b_reverse_early9 | B13: S5 | C13: Precision, t-based confidence intervals, detectable-effect calculations, and the primary nine-test t-based FDR for early AMD reverse models. | D13: =COUNTA(S5b_reverse_early9!A2:A10) -> 9 | E13: OCT; Winkler early AMD
A14: S6a_LDSC_rg90 | B14: S6 | C14: All 90 LDSC genetic-correlation results with precision and detectable-effect calculations. | D14: =COUNTA(S6a_LDSC_rg90!A2:A91) -> 90 | E14: OCT; disease GWAS
A15: S6b_LDSC_early9 | B15: S6 | C15: Nine layer-early AMD genetic correlations with 95% confidence intervals and power-aware interpretation. | D15: =COUNTA(S6b_LDSC_early9!A2:A10) -> 9 | E15: OCT; Winkler early AMD
A16: S6c_h2_figure_source | B16: S6 | C16: Figure 2A heritability point-estimate provenance. No standard errors are imputed. | D16: =COUNTA(S6c_h2_figure_source!A2:A11) -> 10 | E16: Derived results
A17: S7a_MVMR_all18 | B17: S7 | C17: All 18 audited multivariable MR exposure estimates with conditional F and heterogeneity statistics. | D17: =COUNTA(S7a_MVMR_all18!A2:A19) -> 18 | E17: OCT; disease GWAS
A18: S7b_MVMR_early3 | B18: S7 | C18: Validated three-exposure early AMD model. | D18: =COUNTA(S7b_MVMR_early3!A2:A4) -> 3 | E18: Derived results
A19: S7c_MVMR_LOO354 | B19: S7 | C19: Complete leave-one-out refits for the three-exposure early AMD model. | D19: =COUNTA(S7c_MVMR_LOO354!A2:A355) -> 354 | E19: Derived results
A20: S7d_MVMR_influence | B20: S7 | C20: Variant-level Q contributions, leverage, residuals, and Cook distance. | D20: =COUNTA(S7d_MVMR_influence!A2:A119) -> 118 | E20: Derived results
A21: S7e_MVMR_median | B21: S7 | C21: MVMR-Median parametric-bootstrap sensitivity with normal and percentile intervals. | D21: =COUNTA(S7e_MVMR_median!A2:A7) -> 6 | E21: Derived results
A22: S7f_MVMR_Egger | B22: S7 | C22: MVMR-Egger sensitivity including the intercept and residual heterogeneity. | D22: =COUNTA(S7f_MVMR_Egger!A2:A5) -> 4 | E22: Derived results
A23: S7g_exposure_selection | B23: S7 | C23: Outcome-specific exposure-selection audit for the full54 analysis. | D23: =COUNTA(S7g_exposure_selection!A2:A7) -> 6 | E23: Derived results
A24: S8_overlap_scenarios | B24: S8 | C24: All 360 explicit sample-overlap bias scenarios using worst-toward-null shifts. | D24: =COUNTA(S8_overlap_scenarios!A2:A361) -> 360 | E24: Derived results
A25: S8b_overlap_summary | B25: S8 | C25: Scenario-level summary by layer, instrument-strength choice, and observational-association assumption. | D25: =COUNTA(S8b_overlap_summary!A2:A73) -> 72 | E25: Derived results
A26: S9a_coloc_early400 | B26: S9 | C26: All 400 early AMD layer-window colocalization tests under the specified single-causal-variant model. | D26: =COUNTA(S9a_coloc_early400!A2:A401) -> 400 | E26: OCT; Winkler early AMD
A27: S9b_coloc_H4_13 | B27: S9 | C27: Thirteen PP.H4>0.9 tests with distinct-window and connected-interval identifiers. | D27: =COUNTA(S9b_coloc_H4_13!A2:A14) -> 13 | E27: Derived results
A28: S9c_connected_intervals | B28: S9 | C28: Eight connected intervals formed by cross-layer overlap of high-support windows. | D28: =COUNTA(S9c_connected_intervals!A2:A9) -> 8 | E28: Derived results
A29: S9d_specificity_H4 | B29: S9 | C29: Specificity-panel windows with PP.H4>0.5. | D29: =COUNTA(S9d_specificity_H4!A2:A40) -> 39 | E29: OCT; specificity GWAS
A30: S9e_specificity_counts | B30: S9 | C30: Descriptive specificity-panel colocalization counts by disease. | D30: =COUNTA(S9e_specificity_counts!A2:A11) -> 10 | E30: Derived results
A31: S10a_scDRS_main66 | B31: S10 | C31: Primary 66-test scDRS analysis with within-trait and global66 FDR. | D31: =COUNTA(S10a_scDRS_main66!A2:A67) -> 66 | E31: CELLxGENE; GWAS
A32: S10b_scDRS_parameters | B32: S10 | C32: Parameter sensitivity using top 500, top 2,000, and 10 kb window designs. | D32: =COUNTA(S10b_scDRS_parameters!A2:A199) -> 198 | E32: Derived results
A33: S10c_scDRS_LODO | B33: S10 | C33: Leave-one-donor-out analyses with preprocessing and scoring repeated after each omission. | D33: =COUNTA(S10c_scDRS_LODO!A2:A397) -> 396 | E33: Derived results
A34: S10d_atlas_annotation | B34: S10 | C34: Author and ontology labels, exact cell counts, and one-to-one annotation mapping. | D34: =COUNTA(S10d_atlas_annotation!A2:A7) -> 6 | E34: CELLxGENE
A35: S10e_atlas_donors | B35: S10 | C35: Donor-level cell counts in the verified 19,999-cell mini atlas. | D35: =COUNTA(S10e_atlas_donors!A2:A7) -> 6 | E35: CELLxGENE
A36: S11a_Visium_correlations | B36: S11 | C36: Raw, technically adjusted, and matched-random empirical spatial-correlation results. | D36: =COUNTA(S11a_Visium_correlations!A2:A31) -> 30 | E36: GSE234047
A37: S11b_Visium_panel80 | B37: S11 | C37: Sixteen candidates by five sections with valid aliases, detection, zero-variance, and missing status. | D37: =COUNTA(S11b_Visium_panel80!A2:A81) -> 80 | E37: GSE234047
A38: S11c_Visium_DEScriptive | B38: S11 | C38: Descriptive spot-level expression differences between CNV and control spots; donor and disease are confounded. | D38: =COUNTA(S11c_Visium_DEScriptive!A2:A14) -> 13 | E38: GSE234047
A39: S11d_Visium_sections | B39: S11 | C39: Descriptive section-level expression relative to the unweighted control-section mean. | D39: =COUNTA(S11d_Visium_sections!A2:A66) -> 65 | E39: GSE234047
A40: S11e_random_matching | B40: S11 | C40: Audit of detection-rate and expression matching for the random gene-set null. | D40: =COUNTA(S11e_random_matching!A2:A63) -> 62 | E40: GSE234047
...

Sheet S1_SMR_42pairs
A1: source_id | B1: disease | C1: probeID | D1: ProbeChr | E1: Gene | F1: Probe_bp | G1: topSNP | H1: topSNP_chr | I1: topSNP_bp | J1: A1 | K1: A2 | L1: Freq | M1: b_GWAS | N1: se_GWAS | O1: p_GWAS | P1: b_eQTL | Q1: se_eQTL | R1: p_eQTL | S1: b_SMR | T1: se_SMR | U1: p_SMR | V1: p_HEIDI | W1: nsnp_HEIDI | X1: n_tests_within_disease | Y1: pass_within_bonferroni | Z1: pass_HEIDI_0_01 | AA1: pass_HEIDI_0_05 | AB1: legacy42_selected | AC1: p_Bonferroni_global2354 | AD1: q_BH_global2354 | AE1: pass_global_Bonferroni | AF1: pass_global_BH | AG1: symbol_legacy42_annotation | AH1: second_stage_scope | AI1: global_Bonferroni_retained_HEIDI_0_01 | AJ1: global_Bonferroni_retained_HEIDI_0_05 | AK1: HEIDI_0_01_to_0_05
A2: eQTLGen + six disease GWAS | B2: iamdgc_lateamd | C2: ENSG00000177888 | D2: 1 | E2: ENSG00000177888 | F2: 197148622 | G2: rs6671696 | H2: 1 | I2: 197083196 | J2: T | K2: C | L2: 0.0889571 | M2: -0.627876 | N2: 0.0336489 | O2: 5.85464e-81 | P2: -0.123122 | Q2: 0.0208335 | R2: 3.425199e-09 | S2: 5.09963 | T2: 0.905155 | U2: 1.760938e-08 | V2: 0.02637387 | W2: 19 | X2: 409 | Y2: =TRUE() -> TRUE | Z2: =TRUE() -> TRUE | AA2: =FALSE() -> FALSE | AB2: =TRUE() -> 1 | AC2: 4.1452481e-05 | AD2: 4.5552176e-07 | AE2: =TRUE() -> TRUE | AF2: =TRUE() -> TRUE | AG2: ZBTB41 | AH2: Global correction covers 2354 disease-probe tests entering SMR Select; it does not correct the preceding region-selection stage. | AI2: Yes | AJ2: No | AK2: Yes
A3: eQTLGen + six disease GWAS | B3: iamdgc_lateamd | C3: ENSG00000204427 | D3: 6 | E3: ENSG00000204427 | F3: 31662973 | G3: rs150043706 | H3: 6 | I3: 31578465 | J3: A | K3: G | L3: 0.0184049 | M3: -0.492851 | N3: 0.0749458 | O3: 2.5142e-11 | P3: 0.332273 | Q3: 0.0567639 | R3: 4.810398e-09 | S3: -1.48327 | T3: 0.33924 | U3: 1.229249e-05 | V3: 0.04442672 | W3: 5 | X3: 409 | Y3: =TRUE() -> TRUE | Z3: =TRUE() -> TRUE | AA3: =FALSE() -> FALSE | AB3: =TRUE() -> 1 | AC3: 0.028936521 | AD3: 0.00019420484 | AE3: =TRUE() -> TRUE | AF3: =TRUE() -> TRUE | AG3: ABHD16A | AH3: Global correction covers 2354 disease-probe tests entering SMR Select; it does not correct the preceding region-selection stage. | AI3: Yes | AJ3: No | AK3: Yes
A4: eQTLGen + six disease GWAS | B4: iamdgc_lateamd | C4: ENSG00000223534 | D4: 6 | E4: ENSG00000223534 | F4: 32628081 | G4: rs1049225 | H4: 6 | I4: 32627747 | J4: A | K4: G | L4: 0.211656 | M4: -0.170138 | N4: 0.0214328 | O4: 1.88452e-15 | P4: 1.01813 | Q4: 0.0189842 | R4: 0 | S4: -0.167108 | T4: 0.0212805 | U4: 4.073339e-15 | V4: 0.02001716 | W4: 20 | X4: 409 | Y4: =TRUE() -> TRUE | Z4: =TRUE() -> TRUE | AA4: =FALSE() -> FALSE | AB4: =TRUE() -> 1 | AC4: 9.58864e-12 | AD4: 2.7396114e-13 | AE4: =TRUE() -> TRUE | AF4: =TRUE() -> TRUE | AG4: HLA-DQB1-AS1 | AH4: Global correction covers 2354 disease-probe tests entering SMR Select; it does not correct the preceding region-selection stage. | AI4: Yes | AJ4: No | AK4: Yes
A5: eQTLGen + six disease GWAS | B5: iamdgc_lateamd | C5: ENSG00000166997 | D5: 7 | E5: ENSG00000166997 | F5: 99720185 | G5: rs77686669 | H5: 7 | I5: 99744572 | J5: C | K5: T | L5: 0.283231 | M5: 0.0848695 | N5: 0.0200721 | O5: 2.35169e-05 | P5: -0.302547 | Q5: 0.00877516 | R5: 1.731915e-260 | S5: -0.280516 | T5: 0.0668407 | U5: 2.70724e-05 | V5: 0.01131692 | W5: 20 | X5: 409 | Y5: =TRUE() -> TRUE | Z5: =TRUE() -> TRUE | AA5: =FALSE() -> FALSE | AB5: =TRUE() -> 1 | AC5: 0.06372843 | AD5: 0.00041115116 | AE5: =FALSE() -> FALSE | AF5: =TRUE() -> TRUE | AG5: CNPY4 | AH5: Global correction covers 2354 disease-probe tests entering SMR Select; it does not correct the preceding region-selection stage. | AI5: No | AJ5: No | AK5: Yes
A6: eQTLGen + six disease GWAS | B6: iamdgc_lateamd | C6: ENSG00000066923 | D6: 7 | E6: ENSG00000066923 | F6: 99797148 | G6: rs7786505 | H6: 7 | I6: 99817585 | J6: T | K6: G | L6: 0.232106 | M6: 0.125218 | N6: 0.0215867 | O6: 6.5731e-09 | P6: -0.488035 | Q6: 0.00932571 | R6: 0 | S6: -0.256576 | T6: 0.0445028 | U6: 8.146842e-09 | V6: 0.111319 | W6: 20 | X6: 409 | Y6: =TRUE() -> TRUE | Z6: =TRUE() -> TRUE | AA6: =TRUE() -> TRUE | AB6: =TRUE() -> 1 | AC6: 1.9177666e-05 | AD6: 2.2830555e-07 | AE6: =TRUE() -> TRUE | AF6: =TRUE() -> TRUE | AG6: STAG3 | AH6: Global correction covers 2354 disease-probe tests entering SMR Select; it does not correct the preceding region-selection stage. | AI6: Yes | AJ6: Yes | AK6: No
A7: eQTLGen + six disease GWAS | B7: iamdgc_lateamd | C7: ENSG00000078319 | D7: 7 | E7: ENSG00000078319 | F7: 99929073 | G7: rs6979910 | H7: 7 | I7: 99940630 | J7: C | K7: A | L7: 0.180982 | M7: 0.136838 | N7: 0.0226378 | O7: 1.47846e-09 | P7: -0.143261 | Q7: 0.0118696 | R7: 1.528791e-33 | S7: -0.955163 | T7: 0.176727 | U7: 6.489993e-08 | V7: 0.04027323 | W7: 20 | X7: 409 | Y7: =TRUE() -> TRUE | Z7: =TRUE() -> TRUE | AA7: =FALSE() -> FALSE | AB7: =TRUE() -> 1 | AC7: 0.00015277444 | AD7: 1.6081519e-06 | AE7: =TRUE() -> TRUE | AF7: =TRUE() -> TRUE | AG7: PMS2P1 | AH7: Global correction covers 2354 disease-probe tests entering SMR Select; it does not correct the preceding region-selection stage. | AI7: Yes | AJ7: No | AK7: Yes
A8: eQTLGen + six disease GWAS | B8: iamdgc_lateamd | C8: ENSG00000121716 | D8: 7 | E8: ENSG00000121716 | F8: 99949578 | G8: rs6955367 | H8: 7 | I8: 99961194 | J8: G | K8: A | L8: 0.180982 | M8: 0.137724 | N8: 0.0227045 | O8: 1.29458e-09 | P8: 1.02405 | Q8: 0.00855318 | R8: 0 | S8: 0.13449 | T8: 0.0221998 | U8: 1.376843e-09 | V8: 0.1433701 | W8: 20 | X8: 409 | Y8: =TRUE() -> TRUE | Z8: =TRUE() -> TRUE | AA8: =TRUE() -> TRUE | AB8: =TRUE() -> 1 | AC8: 3.2410884e-06 | AD8: 4.6972296e-08 | AE8: =TRUE() -> TRUE | AF8: =TRUE() -> TRUE | AG8: PILRB | AH8: Global correction covers 2354 disease-probe tests entering SMR Select; it does not correct the preceding region-selection stage. | AI8: Yes | AJ8: Yes | AK8: No
A9: eQTLGen + six disease GWAS | B9: iamdgc_lateamd | C9: ENSG00000078487 | D9: 7 | E9: ENSG00000078487 | F9: 100012532 | G9: rs35111986 | H9: 7 | I9: 100000274 | J9: A | K9: C | L9: 0.197342 | M9: 0.141079 | N9: 0.0225005 | O9: 3.54079e-10 | P9: -0.264006 | Q9: 0.0100468 | R9: 3.449447e-152 | S9: -0.534378 | T9: 0.0876197 | U9: 1.068485e-09 | V9: 0.04295994 | W9: 20 | X9: 409 | Y9: =TRUE() -> TRUE | Z9: =TRUE() -> TRUE | AA9: =FALSE() -> FALSE | AB9: =TRUE() -> 1 | AC9: 2.5152137e-06 | AD9: 3.7540503e-08 | AE9: =TRUE() -> TRUE | AF9: =TRUE() -> TRUE | AG9: ZCWPW1 | AH9: Global correction covers 2354 disease-probe tests entering SMR Select; it does not correct the preceding region-selection stage. | AI9: Yes | AJ9: No | AK9: Yes
A10: eQTLGen + six disease GWAS | B10: iamdgc_lateamd | C10: ENSG00000146834 | D10: 7 | E10: ENSG00000146834 | F10: 100029077 | G10: rs67471932 | H10: 7 | I10: 100009985 | J10: G | K10: C | L10: 0.197342 | M10: 0.138412 | N10: 0.0224085 | O10: 6.42614e-10 | P10: -0.301183 | Q10: 0.0100063 | R10: 4.948665e-199 | S10: -0.459561 | T10: 0.075952 | U10: 1.442418e-09 | V10: 0.03288505 | W10: 20 | X10: 409 | Y10: =TRUE() -> TRUE | Z10: =TRUE() -> TRUE | AA10: =FALSE() -> FALSE | AB10: =TRUE() -> 1 | AC10: 3.395452e-06 | AD10: 4.8506457e-08 | AE10: =TRUE() -> TRUE | AF10: =TRUE() -> TRUE | AG10: MEPCE | AH10: Global correction covers 2354 disease-probe tests entering SMR Select; it does not correct the preceding region-selection stage. | AI10: Yes | AJ10: No | AK10: Yes
A11: eQTLGen + six disease GWAS | B11: iamdgc_lateamd | C11: ENSG00000160813 | D11: 7 | E11: ENSG00000160813 | F11: 100033546 | G11: rs11766752 | H11: 7 | I11: 100073292 | J11: G | K11: A | L11: 0.200409 | M11: 0.13778 | N11: 0.0224127 | O11: 7.73232e-10 | P11: -0.0933557 | Q11: 0.0112298 | R11: 9.315502e-17 | S11: -1.47586 | T11: 0.298589 | U11: 7.701511e-07 | V11: 0.2394734 | W11: 20 | X11: 409 | Y11: =TRUE() -> TRUE | Z11: =TRUE() -> TRUE | AA11: =TRUE() -> TRUE | AB11: =TRUE() -> 1 | AC11: 0.0018129357 | AD11: 1.5495177e-05 | AE11: =TRUE() -> TRUE | AF11: =TRUE() -> TRUE | AG11: PPP1R35 | AH11: Global correction covers 2354 disease-probe tests entering SMR Select; it does not correct the preceding region-selection stage. | AI11: Yes | AJ11: Yes | AK11: No
A12: eQTLGen + six disease GWAS | B12: iamdgc_lateamd | C12: ENSG00000246582 | D12: 8 | E12: ENSG00000246582 | F12: 23085211 | G12: rs13254617 | H12: 8 | I12: 23083836 | J12: C | K12: A | L12: 0.456033 | M12: -0.0994794 | N12: 0.0183451 | O12: 5.78895e-08 | P12: 0.616784 | Q12: 0.00856399 | R12: 0 | S12: -0.161287 | T12: 0.0298273 | U12: 6.395943e-08 | V12: 0.3020951 | W12: 20 | X12: 409 | Y12: =TRUE() -> TRUE | Z12: =TRUE() -> TRUE | AA12: =TRUE() -> TRUE | AB12: =TRUE() -> 1 | AC12: 0.0001505605 | AD12: 1.6017074e-06 | AE12: =TRUE() -> TRUE | AF12: =TRUE() -> TRUE | AG12: TNFRSF10A-DT | AH12: Global correction covers 2354 disease-probe tests entering SMR Select; it does not correct the preceding region-selection stage. | AI12: Yes | AJ12: Yes | AK12: No
A13: eQTLGen + six disease GWAS | B13: iamdgc_lateamd | C13: ENSG00000258311 | D13: 12 | E13: ENSG00000258311 | F13: 56114153 | G13: rs3138141 | H13: 12 | I13: 56115778 | J13: A | K13: C | L13: 0.188139 | M13: 0.160869 | N13: 0.0233601 | O13: 5.55392e-12 | P13: -0.757498 | Q13: 0.0101145 | R13: 0 | S13: -0.212369 | T13: 0.0309686 | U13: 7.004858e-12 | V13: 0.9132134 | W13: 20 | X13: 409 | Y13: =TRUE() -> TRUE | Z13: =TRUE() -> TRUE | AA13: =TRUE() -> TRUE | AB13: =TRUE() -> 1 | AC13: 1.6489436e-08 | AD13: 3.1710453e-10 | AE13: =TRUE() -> TRUE | AF13: =TRUE() -> TRUE | AG13: ENSG00000258311 | AH13: Global correction covers 2354 disease-probe tests entering SMR Select; it does not correct the preceding region-selection stage. | AI13: Yes | AJ13: Yes | AK13: No
A14: eQTLGen + six disease GWAS | B14: iamdgc_lateamd | C14: ENSG00000135437 | D14: 12 | E14: ENSG00000135437 | F14: 56116320 | G14: rs56108400 | H14: 12 | I14: 56213297 | J14: T | K14: G | L14: 0.189162 | M14: 0.144781 | N14: 0.0233733 | O14: 5.73667e-10 | P14: -0.770536 | Q14: 0.0192782 | R14: 0 | S14: -0.187897 | T14: 0.0306959 | U14: 9.286315e-10 | V14: 0.2586731 | W14: 20 | X14: 409 | Y14: =TRUE() -> TRUE | Z14: =TRUE() -> TRUE | AA14: =TRUE() -> TRUE | AB14: =TRUE() -> 1 | AC14: 2.1859986e-06 | AD14: 3.312119e-08 | AE14: =TRUE() -> TRUE | AF14: =TRUE() -> TRUE | AG14: RDH5 | AH14: Global correction covers 2354 disease-probe tests entering SMR Select; it does not correct the preceding region-selection stage. | AI14: Yes | AJ14: Yes | AK14: No
A15: eQTLGen + six disease GWAS | B15: iamdgc_lateamd | C15: ENSG00000104879 | D15: 19 | E15: ENSG00000104879 | F15: 45817953 | G15: rs386569 | H15: 19 | I15: 45787046 | J15: G | K15: A | L15: 0.321063 | M15: 0.0772493 | N15: 0.0199599 | O15: 0.000108565 | P15: 0.277959 | Q15: 0.00858524 | R15: 5.898597e-230 | S15: 0.277916 | T15: 0.07232 | U15: 0.0001216059 | V15: 0.04046325 | W15: 20 | X15: 409 | Y15: =TRUE() -> TRUE | Z15: =TRUE() -> TRUE | AA15: =FALSE() -> FALSE | AB15: =TRUE() -> 1 | AC15: 0.28626029 | AD15: 0.0015992195 | AE15: =FALSE() -> FALSE | AF15: =TRUE() -> TRUE | AG15: CKM | AH15: Global correction covers 2354 disease-probe tests entering SMR Select; it does not correct the preceding region-selection stage. | AI15: No | AJ15: No | AK15: Yes
A16: eQTLGen + six disease GWAS | B16: finngen_WET_AMD | C16: ENSG00000204427 | D16: 6 | E16: ENSG00000204427 | F16: 31662973 | G16: rs150043706 | H16: 6 | I16: 31578465 | J16: A | K16: G | L16: 0.0184049 | M16: -0.462004 | N16: 0.0524578 | O16: 1.28351e-18 | P16: 0.332273 | Q16: 0.0567639 | R16: 4.810398e-09 | S16: -1.39043 | T16: 0.285215 | U16: 1.087849e-06 | V16: 0.1944563 | W16: 5 | X16: 409 | Y16: =TRUE() -> TRUE | Z16: =TRUE() -> TRUE | AA16: =TRUE() -> TRUE | AB16: =TRUE() -> 1 | AC16: 0.0025607965 | AD16: 2.1339971e-05 | AE16: =TRUE() -> TRUE | AF16: =TRUE() -> TRUE | AG16: ABHD16A | AH16: Global correction covers 2354 disease-probe tests entering SMR Select; it does not correct the preceding region-selection stage. | AI16: Yes | AJ16: Yes | AK16: No
A17: eQTLGen + six disease GWAS | B17: finngen_WET_AMD | C17: ENSG00000223534 | D17: 6 | E17: ENSG00000223534 | F17: 32628081 | G17: rs1049225 | H17: 6 | I17: 32627747 | J17: A | K17: G | L17: 0.211656 | M17: -0.157641 | N17: 0.021046 | O17: 6.87227e-14 | P17: 1.01813 | Q17: 0.0189842 | R17: 0 | S17: -0.154834 | T17: 0.0208718 | U17: 1.186294e-13 | V17: 0.02980758 | W17: 20 | X17: 409 | Y17: =TRUE() -> TRUE | Z17: =TRUE() -> TRUE | AA17: =FALSE() -> FALSE | AB17: =TRUE() -> 1 | AC17: 2.7925361e-10 | AD17: 6.3466729e-12 | AE17: =TRUE() -> TRUE | AF17: =TRUE() -> TRUE | AG17: HLA-DQB1-AS1 | AH17: Global correction covers 2354 disease-probe tests entering SMR Select; it does not correct the preceding region-selection stage. | AI17: Yes | AJ17: No | AK17: Yes
A18: eQTLGen + six disease GWAS | B18: finngen_WET_AMD | C18: ENSG00000242294 | D18: 7 | E18: ENSG00000242294 | F18: 99936349 | G18: rs7799894 | H18: 7 | I18: 99950427 | J18: T | K18: G | L18: 0.179959 | M18: 0.0881359 | N18: 0.0219032 | O18: 5.72453e-05 | P18: 0.270438 | Q18: 0.0161033 | R18: 2.700241e-63 | S18: 0.3259 | T18: 0.0832839 | U18: 9.110938e-05 | V18: 0.0913346 | W18: 20 | X18: 409 | Y18: =TRUE() -> TRUE | Z18: =TRUE() -> TRUE | AA18: =TRUE() -> TRUE | AB18: =TRUE() -> 1 | AC18: 0.21447148 | AD18: 0.001218588 | AE18: =FALSE() -> FALSE | AF18: =TRUE() -> TRUE | AG18: STAG3L5P | AH18: Global correction covers 2354 disease-probe tests entering SMR Select; it does not correct the preceding region-selection stage. | AI18: No | AJ18: No | AK18: No
A19: eQTLGen + six disease GWAS | B19: finngen_WET_AMD | C19: ENSG00000121716 | D19: 7 | E19: ENSG00000121716 | F19: 99949578 | G19: rs6955367 | H19: 7 | I19: 99961194 | J19: G | K19: A | L19: 0.180982 | M19: 0.0878728 | N19: 0.0218997 | O19: 6.00745e-05 | P19: 1.02405 | Q19: 0.00855318 | R19: 0 | S19: 0.0858095 | T19: 0.0213975 | U19: 6.06519e-05 | V19: 0.2345667 | W19: 20 | X19: 409 | Y19: =TRUE() -> TRUE | Z19: =TRUE() -> TRUE | AA19: =TRUE() -> TRUE | AB19: =TRUE() -> 1 | AC19: 0.14277457 | AD19: 0.00085493756 | AE19: =FALSE() -> FALSE | AF19: =TRUE() -> TRUE | AG19: PILRB | AH19: Global correction covers 2354 disease-probe tests entering SMR Select; it does not correct the preceding region-selection stage. | AI19: No | AJ19: No | AK19: No
A20: eQTLGen + six disease GWAS | B20: finngen_WET_AMD | C20: ENSG00000078487 | D20: 7 | E20: ENSG00000078487 | F20: 100012532 | G20: rs35111986 | H20: 7 | I20: 100000274 | J20: A | K20: C | L20: 0.197342 | M20: 0.0865902 | N20: 0.0213739 | O20: 5.0953e-05 | P20: -0.264006 | Q20: 0.0100468 | R20: 3.449447e-152 | S20: -0.327985 | T20: 0.0819163 | U20: 6.230442e-05 | V20: 0.06183538 | W20: 20 | X20: 409 | Y20: =TRUE() -> TRUE | Z20: =TRUE() -> TRUE | AA20: =TRUE() -> TRUE | AB20: =TRUE() -> 1 | AC20: 0.1466646 | AD20: 0.0008678379 | AE20: =FALSE() -> FALSE | AF20: =TRUE() -> TRUE | AG20: ZCWPW1 | AH20: Global correction covers 2354 disease-probe tests entering SMR Select; it does not correct the preceding region-selection stage. | AI20: No | AJ20: No | AK20: No
A21: eQTLGen + six disease GWAS | B21: finngen_WET_AMD | C21: ENSG00000146834 | D21: 7 | E21: ENSG00000146834 | F21: 100029077 | G21: rs67471932 | H21: 7 | I21: 100009985 | J21: G | K21: C | L21: 0.197342 | M21: 0.0863224 | N21: 0.0213787 | O21: 5.39598e-05 | P21: -0.301183 | Q21: 0.0100063 | R21: 4.948665e-199 | S21: -0.286611 | T21: 0.0716182 | U21: 6.282855e-05 | V21: 0.09229015 | W21: 20 | X21: 409 | Y21: =TRUE() -> TRUE | Z21: =TRUE() -> TRUE | AA21: =TRUE() -> TRUE | AB21: =TRUE() -> 1 | AC21: 0.14789841 | AD21: 0.00086999063 | AE21: =FALSE() -> FALSE | AF21: =TRUE() -> TRUE | AG21: MEPCE | AH21: Global correction covers 2354 disease-probe tests entering SMR Select; it does not correct the preceding region-selection stage. | AI21: No | AJ21: No | AK21: No
A22: eQTLGen + six disease GWAS | B22: finngen_WET_AMD | C22: ENSG00000107669 | D22: 10 | E22: ENSG00000107669 | F22: 123594127 | G22: rs17102809 | H22: 10 | I22: 123728523 | J22: C | K22: A | L22: 0.0746421 | M22: 0.197332 | N22: 0.026332 | O22: 6.6819e-14 | P22: 0.176808 | Q22: 0.0141345 | R22: 6.665824e-36 | S22: 1.11608 | T22: 0.17361 | U22: 1.287548e-10 | V22: 0.09100835 | W22: 20 | X22: 409 | Y22: =TRUE() -> TRUE | Z22: =TRUE() -> TRUE | AA22: =TRUE() -> TRUE | AB22: =TRUE() -> 1 | AC22: 3.030888e-07 | AD22: 4.8109333e-09 | AE22: =TRUE() -> TRUE | AF22: =TRUE() -> TRUE | AG22: ATE1 | AH22: Global correction covers 2354 disease-probe tests entering SMR Select; it does not correct the preceding region-selection stage. | AI22: Yes | AJ22: Yes | AK22: No
A23: eQTLGen + six disease GWAS | B23: finngen_WET_AMD | C23: ENSG00000095574 | D23: 10 | E23: ENSG00000095574 | F23: 124759327 | G23: rs41291346 | H23: 10 | I23: 124813127 | J23: T | K23: C | L23: 0.0286299 | M23: 0.275048 | N23: 0.0584265 | O23: 2.50651e-06 | P23: -0.19231 | Q23: 0.0245512 | R23: 4.763605e-15 | S23: -1.43024 | T23: 0.354462 | U23: 5.461305e-05 | V23: 0.02182973 | W23: 12 | X23: 409 | Y23: =TRUE() -> TRUE | Z23: =TRUE() -> TRUE | AA23: =FALSE() -> FALSE | AB23: =TRUE() -> 1 | AC23: 0.12855912 | AD23: 0.00078389707 | AE23: =FALSE() -> FALSE | AF23: =TRUE() -> TRUE | AG23: IKZF5 | AH23: Global correction covers 2354 disease-probe tests entering SMR Select; it does not correct the preceding region-selection stage. | AI23: No | AJ23: No | AK23: Yes
A24: eQTLGen + six disease GWAS | B24: finngen_WET_AMD | C24: ENSG00000258311 | D24: 12 | E24: ENSG00000258311 | F24: 56114153 | G24: rs3138141 | H24: 12 | I24: 56115778 | J24: A | K24: C | L24: 0.188139 | M24: 0.110685 | N24: 0.0239036 | O24: 3.64821e-06 | P24: -0.757498 | Q24: 0.0101145 | R24: 0 | S24: -0.146119 | T24: 0.0316163 | U24: 3.807022e-06 | V24: 0.04865361 | W24: 20 | X24: 409 | Y24: =TRUE() -> TRUE | Z24: =TRUE() -> TRUE | AA24: =FALSE() -> FALSE | AB24: =TRUE() -> 1 | AC24: 0.0089617298 | AD24: 6.6878581e-05 | AE24: =TRUE() -> TRUE | AF24: =TRUE() -> TRUE | AG24: ENSG00000258311 | AH24: Global correction covers 2354 disease-probe tests entering SMR Select; it does not correct the preceding region-selection stage. | AI24: Yes | AJ24: No | AK24: Yes
A25: eQTLGen + six disease GWAS | B25: finngen_DRY_AMD | C25: ENSG00000204427 | D25: 6 | E25: ENSG00000204427 | F25: 31662973 | G25: rs150043706 | H25: 6 | I25: 31578465 | J25: A | K25: G | L25: 0.0184049 | M25: -0.389229 | N25: 0.0460882 | O25: 3.03249e-17 | P25: 0.332273 | Q25: 0.0567639 | R25: 4.810398e-09 | S25: -1.17141 | T25: 0.243489 | U25: 1.502082e-06 | V25: 0.1425249 | W25: 5 | X25: 409 | Y25: =TRUE() -> TRUE | Z25: =TRUE() -> TRUE | AA25: =TRUE() -> TRUE | AB25: =TRUE() -> 1 | AC25: 0.003535901 | AD25: 2.8982795e-05 | AE25: =TRUE() -> TRUE | AF25: =TRUE() -> TRUE | AG25: ABHD16A | AH25: Global correction covers 2354 disease-probe tests entering SMR Select; it does not correct the preceding region-selection stage. | AI25: Yes | AJ25: Yes | AK25: No
A26: eQTLGen + six disease GWAS | B26: finngen_DRY_AMD | C26: ENSG00000168477 | D26: 6 | E26: ENSG00000168477 | F26: 32046021 | G26: rs2269426 | H26: 6 | I26: 32076499 | J26: A | K26: G | L26: 0.41002 | M26: 0.0832649 | N26: 0.016326 | O26: 3.39399e-07 | P26: 0.434818 | Q26: 0.0181727 | R26: 1.603994e-126 | S26: 0.191494 | T26: 0.0383902 | U26: 6.098122e-07 | V26: 0.01684781 | W26: 20 | X26: 409 | Y26: =TRUE() -> TRUE | Z26: =TRUE() -> TRUE | AA26: =FALSE() -> FALSE | AB26: =TRUE() -> 1 | AC26: 0.0014354979 | AD26: 1.2932414e-05 | AE26: =TRUE() -> TRUE | AF26: =TRUE() -> TRUE | AG26: TNXB | AH26: Global correction covers 2354 disease-probe tests entering SMR Select; it does not correct the preceding region-selection stage. | AI26: Yes | AJ26: No | AK26: Yes
A27: eQTLGen + six disease GWAS | B27: finngen_DRY_AMD | C27: ENSG00000107669 | D27: 10 | E27: ENSG00000107669 | F27: 123594127 | G27: rs17102809 | H27: 10 | I27: 123728523 | J27: C | K27: A | L27: 0.0746421 | M27: 0.132195 | N27: 0.023856 | O27: 3.0013e-08 | P27: 0.176808 | Q27: 0.0141345 | R27: 6.665824e-36 | S27: 0.747674 | T27: 0.147572 | U27: 4.051962e-07 | V27: 0.1742341 | W27: 20 | X27: 409 | Y27: =TRUE() -> TRUE | Z27: =TRUE() -> TRUE | AA27: =TRUE() -> TRUE | AB27: =TRUE() -> 1 | AC27: 0.00095383185 | AD27: 8.9143164e-06 | AE27: =TRUE() -> TRUE | AF27: =TRUE() -> TRUE | AG27: ATE1 | AH27: Global correction covers 2354 disease-probe tests entering SMR Select; it does not correct the preceding region-selection stage. | AI27: Yes | AJ27: Yes | AK27: No
A28: eQTLGen + six disease GWAS | B28: finngen_DRY_AMD | C28: ENSG00000095574 | D28: 10 | E28: ENSG00000095574 | F28: 124759327 | G28: rs41291346 | H28: 10 | I28: 124813127 | J28: T | K28: C | L28: 0.0286299 | M28: 0.283451 | N28: 0.0521737 | O28: 5.54651e-08 | P28: -0.19231 | Q28: 0.0245512 | R28: 4.763605e-15 | S28: -1.47393 | T28: 0.330169 | U28: 8.038059e-06 | V28: 0.0258079 | W28: 12 | X28: 409 | Y28: =TRUE() -> TRUE | Z28: =TRUE() -> TRUE | AA28: =FALSE() -> FALSE | AB28: =TRUE() -> 1 | AC28: 0.018921591 | AD28: 0.00013059411 | AE28: =TRUE() -> TRUE | AF28: =TRUE() -> TRUE | AG28: IKZF5 | AH28: Global correction covers 2354 disease-probe tests entering SMR Select; it does not correct the preceding region-selection stage. | AI28: Yes | AJ28: No | AK28: Yes
A29: eQTLGen + six disease GWAS | B29: finngen_DM_MACULOPATHY | C29: ENSG00000204421 | D29: 6 | E29: ENSG00000204421 | F29: 31688023 | G29: rs3117572 | H29: 6 | I29: 31717692 | J29: A | K29: G | L29: 0.154397 | M29: -0.229691 | N29: 0.0311048 | O29: 1.53109e-13 | P29: 0.112507 | Q29: 0.0183901 | R29: 9.487579e-10 | S29: -2.04157 | T29: 0.433356 | U29: 2.464264e-06 | V29: 0.02145565 | W29: 20 | X29: 409 | Y29: =TRUE() -> TRUE | Z29: =TRUE() -> TRUE | AA29: =FALSE() -> FALSE | AB29: =TRUE() -> 1 | AC29: 0.0058008775 | AD29: 4.3946041e-05 | AE29: =TRUE() -> TRUE | AF29: =TRUE() -> TRUE | AG29: LY6G6C | AH29: Global correction covers 2354 disease-probe tests entering SMR Select; it does not correct the preceding region-selection stage. | AI29: Yes | AJ29: No | AK29: Yes
A30: eQTLGen + six disease GWAS | B30: finngen_DM_MACULOPATHY | C30: ENSG00000204371 | D30: 6 | E30: ENSG00000204371 | F30: 31856500 | G30: rs3020644 | H30: 6 | I30: 31894626 | J30: G | K30: A | L30: 0.391616 | M30: 0.178804 | N30: 0.022123 | O30: 6.3577e-16 | P30: -0.0882345 | Q30: 0.0123664 | R30: 9.678692e-13 | S30: -2.02646 | T30: 0.378855 | U30: 8.848301e-08 | V30: 0.1307901 | W30: 20 | X30: 409 | Y30: =TRUE() -> TRUE | Z30: =TRUE() -> TRUE | AA30: =TRUE() -> TRUE | AB30: =TRUE() -> 1 | AC30: 0.00020828901 | AD30: 2.1473093e-06 | AE30: =TRUE() -> TRUE | AF30: =TRUE() -> TRUE | AG30: EHMT2 | AH30: Global correction covers 2354 disease-probe tests entering SMR Select; it does not correct the preceding region-selection stage. | AI30: Yes | AJ30: Yes | AK30: No
A31: eQTLGen + six disease GWAS | B31: finngen_DM_MACULOPATHY | C31: ENSG00000135414 | D31: 12 | E31: ENSG00000135414 | F31: 56143987 | G31: rs7302200 | H31: 12 | I31: 56449435 | J31: A | K31: G | L31: 0.328221 | M31: 0.106881 | N31: 0.0235188 | O31: 5.50681e-06 | P31: -0.0674603 | Q31: 0.00861715 | R31: 4.933293e-15 | S31: -1.58435 | T31: 0.403115 | U31: 8.484821e-05 | V31: 0.4203344 | W31: 19 | X31: 409 | Y31: =TRUE() -> TRUE | Z31: =TRUE() -> TRUE | AA31: =TRUE() -> TRUE | AB31: =TRUE() -> 1 | AC31: 0.19973269 | AD31: 0.001147889 | AE31: =FALSE() -> FALSE | AF31: =TRUE() -> TRUE | AG31: GDF11 | AH31: Global correction covers 2354 disease-probe tests entering SMR Select; it does not correct the preceding region-selection stage. | AI31: No | AJ31: No | AK31: No
A32: eQTLGen + six disease GWAS | B32: finngen_DM_MACULOPATHY | C32: ENSG00000139531 | D32: 12 | E32: ENSG00000139531 | F32: 56395694 | G32: rs1873914 | H32: 12 | I32: 56379427 | J32: C | K32: G | L32: 0.391616 | M32: 0.104598 | N32: 0.0223139 | O32: 2.76478e-06 | P32: -0.336612 | Q32: 0.00796648 | R32: 0 | S32: -0.310738 | T32: 0.0666964 | U32: 3.177665e-06 | V32: 0.07089155 | W32: 20 | X32: 409 | Y32: =TRUE() -> TRUE | Z32: =TRUE() -> TRUE | AA32: =TRUE() -> TRUE | AB32: =TRUE() -> 1 | AC32: 0.0074802234 | AD32: 5.6242281e-05 | AE32: =TRUE() -> TRUE | AF32: =TRUE() -> TRUE | AG32: SUOX | AH32: Global correction covers 2354 disease-probe tests entering SMR Select; it does not correct the preceding region-selection stage. | AI32: Yes | AJ32: Yes | AK32: No
A33: eQTLGen + six disease GWAS | B33: finngen_DM_MACULOPATHY | C33: ENSG00000065361 | D33: 12 | E33: ENSG00000065361 | F33: 56485465 | G33: rs11171739 | H33: 12 | I33: 56470625 | J33: C | K33: T | L33: 0.415133 | M33: 0.0897154 | N33: 0.0219755 | O33: 4.45513e-05 | P33: -0.167927 | Q33: 0.0081462 | R33: 2.046786e-94 | S33: -0.534251 | T33: 0.133405 | U33: 6.208607e-05 | V33: 0.0571794 | W33: 20 | X33: 409 | Y33: =TRUE() -> TRUE | Z33: =TRUE() -> TRUE | AA33: =TRUE() -> TRUE | AB33: =TRUE() -> 1 | AC33: 0.14615061 | AD33: 0.0008678379 | AE33: =FALSE() -> FALSE | AF33: =TRUE() -> TRUE | AG33: ERBB3 | AH33: Global correction covers 2354 disease-probe tests entering SMR Select; it does not correct the preceding region-selection stage. | AI33: No | AJ33: No | AK33: No
A34: eQTLGen + six disease GWAS | B34: finngen_H7_RETIVASCOCCLUSION | C34: ENSG00000100311 | D34: 22 | E34: ENSG00000100311 | F34: 39630060 | G34: rs5757573 | H34: 22 | I34: 39633622 | J34: C | K34: T | L34: 0.379346 | M34: -0.0898722 | N34: 0.0222673 | O34: 5.43576e-05 | P34: -0.356257 | Q34: 0.00866145 | R34: 0 | S34: 0.252268 | T34: 0.0628037 | U34: 5.900128e-05 | V34: 0.7129784 | W34: 20 | X34: 409 | Y34: =TRUE() -> TRUE | Z34: =TRUE() -> TRUE | AA34: =TRUE() -> TRUE | AB34: =TRUE() -> 1 | AC34: 0.13888901 | AD34: 0.0008366808 | AE34: =FALSE() -> FALSE | AF34: =TRUE() -> TRUE | AG34: PDGFB | AH34: Global correction covers 2354 disease-probe tests entering SMR Select; it does not correct the preceding region-selection stage. | AI34: No | AJ34: No | AK34: No
A35: eQTLGen + six disease GWAS | B35: winkler_earlyamd | C35: ENSG00000177888 | D35: 1 | E35: ENSG00000177888 | F35: 197148622 | G35: rs6671696 | H35: 1 | I35: 197083196 | J35: T | K35: C | L35: 0.0889571 | M35: -0.1535 | N35: 0.024 | O35: 1.603e-10 | P35: -0.123122 | Q35: 0.0208335 | R35: 3.425199e-09 | S35: 1.24673 | T35: 0.287231 | U35: 1.42141e-05 | V35: 0.04225988 | W35: 20 | X35: 309 | Y35: =TRUE() -> TRUE | Z35: =TRUE() -> TRUE | AA35: =FALSE() -> FALSE | AB35: =TRUE() -> 1 | AC35: 0.033459991 | AD35: 0.00022158935 | AE35: =TRUE() -> TRUE | AF35: =TRUE() -> TRUE | AG35: ZBTB41 | AH35: Global correction covers 2354 disease-probe tests entering SMR Select; it does not correct the preceding region-selection stage. | AI35: Yes | AJ35: No | AK35: Yes
A36: eQTLGen + six disease GWAS | B36: winkler_earlyamd | C36: ENSG00000204356 | D36: 6 | E36: ENSG00000204356 | F36: 31923375 | G36: rs541862 | H36: 6 | I36: 31916951 | J36: C | K36: T | L36: 0.0879346 | M36: -0.2123 | N36: 0.0245 | O36: 4.629e-18 | P36: -0.462702 | Q36: 0.0298006 | R36: 2.292108e-54 | S36: 0.458826 | T36: 0.0606378 | U36: 3.82909e-14 | V36: 0.08492657 | W36: 20 | X36: 309 | Y36: =TRUE() -> TRUE | Z36: =TRUE() -> TRUE | AA36: =TRUE() -> TRUE | AB36: =TRUE() -> 1 | AC36: 9.0136779e-11 | AD36: 2.198458e-12 | AE36: =TRUE() -> TRUE | AF36: =TRUE() -> TRUE | AG36: NELFE | AH36: Global correction covers 2354 disease-probe tests entering SMR Select; it does not correct the preceding region-selection stage. | AI36: Yes | AJ36: Yes | AK36: No
A37: eQTLGen + six disease GWAS | B37: winkler_earlyamd | C37: ENSG00000168477 | D37: 6 | E37: ENSG00000168477 | F37: 32046021 | G37: rs2269426 | H37: 6 | I37: 32076499 | J37: A | K37: G | L37: 0.41002 | M37: 0.0706 | N37: 0.0144 | O37: 8.948e-07 | P37: 0.434818 | Q37: 0.0181727 | R37: 1.603994e-126 | S37: 0.162367 | T37: 0.0338054 | U37: 1.563179e-06 | V37: 0.04988382 | W37: 20 | X37: 309 | Y37: =TRUE() -> TRUE | Z37: =TRUE() -> TRUE | AA37: =FALSE() -> FALSE | AB37: =TRUE() -> 1 | AC37: 0.0036797234 | AD37: 2.991645e-05 | AE37: =TRUE() -> TRUE | AF37: =TRUE() -> TRUE | AG37: TNXB | AH37: Global correction covers 2354 disease-probe tests entering SMR Select; it does not correct the preceding region-selection stage. | AI37: Yes | AJ37: No | AK37: Yes
A38: eQTLGen + six disease GWAS | B38: winkler_earlyamd | C38: ENSG00000121716 | D38: 7 | E38: ENSG00000121716 | F38: 99949578 | G38: rs6955367 | H38: 7 | I38: 99961194 | J38: G | K38: A | L38: 0.180982 | M38: 0.0679 | N38: 0.0177 | O38: 0.0001256 | P38: 1.02405 | Q38: 0.00855318 | R38: 0 | S38: 0.0663056 | T38: 0.0172933 | U38: 0.0001259784 | V38: 0.8455625 | W38: 20 | X38: 309 | Y38: =TRUE() -> TRUE | Z38: =TRUE() -> TRUE | AA38: =TRUE() -> TRUE | AB38: =TRUE() -> 1 | AC38: 0.29655315 | AD38: 0.0016475175 | AE38: =FALSE() -> FALSE | AF38: =TRUE() -> TRUE | AG38: PILRB | AH38: Global correction covers 2354 disease-probe tests entering SMR Select; it does not correct the preceding region-selection stage. | AI38: No | AJ38: No | AK38: No
A39: eQTLGen + six disease GWAS | B39: winkler_earlyamd | C39: ENSG00000104689 | D39: 8 | E39: ENSG00000104689 | F39: 23065302 | G39: rs73224403 | H39: 8 | I39: 23083488 | J39: T | K39: G | L39: 0.221881 | M39: -0.0684 | N39: 0.0178 | O39: 0.000122 | P39: 0.298427 | Q39: 0.0101817 | R39: 7.734144e-189 | S39: -0.229202 | T39: 0.0601565 | U39: 0.0001389156 | V39: 0.08932724 | W39: 20 | X39: 309 | Y39: =TRUE() -> TRUE | Z39: =TRUE() -> TRUE | AA39: =TRUE() -> TRUE | AB39: =TRUE() -> 1 | AC39: 0.32700732 | AD39: 0.0017967435 | AE39: =FALSE() -> FALSE | AF39: =TRUE() -> TRUE | AG39: TNFRSF10A | AH39: Global correction covers 2354 disease-probe tests entering SMR Select; it does not correct the preceding region-selection stage. | AI39: No | AJ39: No | AK39: No
A40: eQTLGen + six disease GWAS | B40: winkler_earlyamd | C40: ENSG00000246582 | D40: 8 | E40: ENSG00000246582 | F40: 23085211 | G40: rs13254617 | H40: 8 | I40: 23083836 | J40: C | K40: A | L40: 0.456033 | M40: -0.0653 | N40: 0.0146 | O40: 7.593e-06 | P40: 0.616784 | Q40: 0.00856399 | R40: 0 | S40: -0.105872 | T40: 0.0237168 | U40: 8.044242e-06 | V40: 0.01871418 | W40: 20 | X40: 309 | Y40: =TRUE() -> TRUE | Z40: =TRUE() -> TRUE | AA40: =FALSE() -> FALSE | AB40: =TRUE() -> 1 | AC40: 0.018936146 | AD40: 0.00013059411 | AE40: =TRUE() -> TRUE | AF40: =TRUE() -> TRUE | AG40: TNFRSF10A-DT | AH40: Global correction covers 2354 disease-probe tests entering SMR Select; it does not correct the preceding region-selection stage. | AI40: Yes | AJ40: No | AK40: Yes
...

Sheet S2_SMR_2354tests
A1: source_id | B1: disease | C1: probeID | D1: ProbeChr | E1: Gene | F1: Probe_bp | G1: topSNP | H1: topSNP_chr | I1: topSNP_bp | J1: A1 | K1: A2 | L1: Freq | M1: b_GWAS | N1: se_GWAS | O1: p_GWAS | P1: b_eQTL | Q1: se_eQTL | R1: p_eQTL | S1: b_SMR | T1: se_SMR | U1: p_SMR | V1: p_HEIDI | W1: nsnp_HEIDI | X1: n_tests_within_disease | Y1: pass_within_bonferroni | Z1: pass_HEIDI_0_01 | AA1: pass_HEIDI_0_05 | AB1: legacy42_selected | AC1: p_Bonferroni_global2354 | AD1: q_BH_global2354 | AE1: pass_global_Bonferroni | AF1: pass_global_BH | AG1: symbol_legacy42_annotation | AH1: second_stage_scope | AI1: retained_global_Bonferroni_HEIDI_0_01 | AJ1: retained_global_Bonferroni_HEIDI_0_05 | AK1: retained_global_BH_HEIDI_0_01
A2: eQTLGen + six disease GWAS | B2: iamdgc_lateamd | C2: ENSG00000007341 | D2: 1 | E2: ENSG00000007341 | F2: 113114793 | G2: rs10745330 | H2: 1 | I2: 113083439 | J2: T | K2: C | L2: 0.480573 | M2: -0.0259706 | N2: 0.0173062 | O2: 0.133446 | P2: 0.474066 | Q2: 0.00748603 | R2: 0 | S2: -0.0547827 | T2: 0.0365161 | U2: 0.1335544 | V2: 0.007709508 | W2: 20 | X2: 409 | Y2: No | Z2: No | AA2: No | AB2: No | AC2: 1 | AD2: 0.40306033 | AE2: No | AF2: No | AH2: Global correction covers 2354 disease-probe tests entering SMR Select; it does not correct the preceding region-selection stage. | AI2: No | AJ2: No | AK2: No
A3: eQTLGen + six disease GWAS | B3: iamdgc_lateamd | C3: ENSG00000116489 | D3: 1 | E3: ENSG00000116489 | F3: 113188018 | G3: rs2932539 | H3: 1 | I3: 113215786 | J3: A | K3: G | L3: 0.246421 | M3: -0.0483137 | N3: 0.0198648 | O3: 0.014983 | P3: 0.0965549 | Q3: 0.0135148 | R3: 9.039006e-13 | S3: -0.500376 | T3: 0.21733 | U3: 0.02131415 | V3: 0.5244411 | W3: 20 | X3: 409 | Y3: No | Z3: Yes | AA3: Yes | AB3: No | AC3: 1 | AD3: 0.12327644 | AE3: No | AF3: No | AH3: Global correction covers 2354 disease-probe tests entering SMR Select; it does not correct the preceding region-selection stage. | AI3: No | AJ3: No | AK3: No
A4: eQTLGen + six disease GWAS | B4: iamdgc_lateamd | C4: ENSG00000238975 | D4: 1 | E4: ENSG00000238975 | F4: 113195260 | G4: rs3790612 | H4: 1 | I4: 113084146 | J4: A | K4: G | L4: 0.248466 | M4: -0.0484273 | N4: 0.019723 | O4: 0.0140491 | P4: 0.13487 | Q4: 0.0223613 | R4: 1.625498e-09 | S4: -0.359067 | T4: 0.157891 | U4: 0.02295718 | V4: 0.5158288 | W4: 18 | X4: 409 | Y4: No | Z4: Yes | AA4: Yes | AB4: No | AC4: 1 | AD4: 0.13116797 | AE4: No | AF4: No | AH4: Global correction covers 2354 disease-probe tests entering SMR Select; it does not correct the preceding region-selection stage. | AI4: No | AJ4: No | AK4: No
A5: eQTLGen + six disease GWAS | B5: iamdgc_lateamd | C5: ENSG00000155363 | D5: 1 | E5: ENSG00000155363 | F5: 113229565 | G5: rs3748655 | H5: 1 | I5: 113217311 | J5: C | K5: G | L5: 0.185072 | M5: 0.0166721 | N5: 0.0233169 | O5: 0.474595 | P5: 0.273768 | Q5: 0.0107385 | R5: 2.28585e-143 | S5: 0.0608986 | T5: 0.0852037 | U5: 0.474769 | V5: 0.3723223 | W5: 20 | X5: 409 | Y5: No | Z5: Yes | AA5: Yes | AB5: No | AC5: 1 | AD5: 0.77513939 | AE5: No | AF5: No | AH5: Global correction covers 2354 disease-probe tests entering SMR Select; it does not correct the preceding region-selection stage. | AI5: No | AJ5: No | AK5: No
A6: eQTLGen + six disease GWAS | B6: iamdgc_lateamd | C6: ENSG00000155366 | D6: 1 | E6: ENSG00000155366 | F6: 113246892 | G6: rs75472514 | H6: 1 | I6: 113243607 | J6: C | K6: A | L6: 0.0398773 | M6: -0.0531265 | N6: 0.0453749 | O6: 0.241666 | P6: 0.515289 | Q6: 0.0208705 | R6: 1.376431e-134 | S6: -0.1031 | T6: 0.0881561 | U6: 0.2421941 | V6: 0.01159441 | W6: 20 | X6: 409 | Y6: No | Z6: Yes | AA6: No | AB6: No | AC6: 1 | AD6: 0.55785216 | AE6: No | AF6: No | AH6: Global correction covers 2354 disease-probe tests entering SMR Select; it does not correct the preceding region-selection stage. | AI6: No | AJ6: No | AK6: No
A7: eQTLGen + six disease GWAS | B7: iamdgc_lateamd | C7: ENSG00000155380 | D7: 1 | E7: ENSG00000155380 | F7: 113477052 | G7: rs7169 | H7: 1 | I7: 113455099 | J7: G | K7: A | L7: 0.436605 | M7: 0.026351 | N7: 0.0174551 | O7: 0.131134 | P7: 0.125393 | Q7: 0.00807102 | R7: 1.973416e-54 | S7: 0.210147 | T7: 0.139859 | U7: 0.1329505 | V7: 0.1073075 | W7: 20 | X7: 409 | Y7: No | Z7: Yes | AA7: Yes | AB7: No | AC7: 1 | AD7: 0.40175286 | AE7: No | AF7: No | AH7: Global correction covers 2354 disease-probe tests entering SMR Select; it does not correct the preceding region-selection stage. | AI7: No | AJ7: No | AK7: No
A8: eQTLGen + six disease GWAS | B8: iamdgc_lateamd | C8: ENSG00000226419 | D8: 1 | E8: ENSG00000226419 | F8: 113521925 | G8: rs6670866 | H8: 1 | I8: 113428827 | J8: A | K8: G | L8: 0.424335 | M8: 0.01303 | N8: 0.0176711 | O8: 0.460901 | P8: 0.120109 | Q8: 0.0193619 | R8: 5.525599e-10 | S8: 0.108484 | T8: 0.148161 | U8: 0.4640418 | V8: 0.2186909 | W8: 13 | X8: 409 | Y8: No | Z8: Yes | AA8: Yes | AB8: No | AC8: 1 | AD8: 0.76980578 | AE8: No | AF8: No | AH8: Global correction covers 2354 disease-probe tests entering SMR Select; it does not correct the preceding region-selection stage. | AI8: No | AJ8: No | AK8: No
A9: eQTLGen + six disease GWAS | B9: iamdgc_lateamd | C9: ENSG00000236066 | D9: 1 | E9: ENSG00000236066 | F9: 113570276 | G9: rs6681552 | H9: 1 | I9: 113434265 | J9: G | K9: A | L9: 0.447853 | M9: 0.0308876 | N9: 0.0175262 | O9: 0.0780064 | P9: 0.100103 | Q9: 0.0175201 | R9: 1.106099e-08 | S9: 0.308559 | T9: 0.183222 | U9: 0.09216738 | V9: 0.4038007 | W9: 15 | X9: 409 | Y9: No | Z9: Yes | AA9: Yes | AB9: No | AC9: 1 | AD9: 0.32022208 | AE9: No | AF9: No | AH9: Global correction covers 2354 disease-probe tests entering SMR Select; it does not correct the preceding region-selection stage. | AI9: No | AJ9: No | AK9: No
A10: eQTLGen + six disease GWAS | B10: iamdgc_lateamd | C10: ENSG00000238198 | D10: 1 | E10: ENSG00000238198 | F10: 113585018 | G10: rs1766862 | H10: 1 | I10: 113615193 | J10: C | K10: T | L10: 0.398773 | M10: -0.00210073 | N10: 0.0179436 | O10: 0.906801 | P10: -0.140789 | Q10: 0.0206635 | R10: 9.531894e-12 | S10: 0.0149211 | T10: 0.127469 | U10: 0.9068151 | V10: 0.3735314 | W10: 20 | X10: 409 | Y10: No | Z10: Yes | AA10: Yes | AB10: No | AC10: 1 | AD10: 0.96155079 | AE10: No | AF10: No | AH10: Global correction covers 2354 disease-probe tests entering SMR Select; it does not correct the preceding region-selection stage. | AI10: No | AJ10: No | AK10: No
A11: eQTLGen + six disease GWAS | B11: iamdgc_lateamd | C11: ENSG00000198799 | D11: 1 | E11: ENSG00000198799 | F11: 113642826 | G11: rs7548091 | H11: 1 | I11: 113672827 | J11: G | K11: A | L11: 0.135992 | M11: 0.00602644 | N11: 0.0247712 | O11: 0.807786 | P11: -0.151314 | Q11: 0.0116982 | R11: 2.863687e-38 | S11: -0.0398275 | T11: 0.163737 | U11: 0.8078186 | V11: 0.7944362 | W11: 20 | X11: 409 | Y11: No | Z11: Yes | AA11: Yes | AB11: No | AC11: 1 | AD11: 0.92756965 | AE11: No | AF11: No | AH11: Global correction covers 2354 disease-probe tests entering SMR Select; it does not correct the preceding region-selection stage. | AI11: No | AJ11: No | AK11: No
A12: eQTLGen + six disease GWAS | B12: iamdgc_lateamd | C12: ENSG00000000971 | D12: 1 | E12: ENSG00000000971 | F12: 196668821 | G12: rs203683 | H12: 1 | I12: 196678432 | J12: G | K12: C | L12: 0.396728 | M12: 0.862097 | N12: 0.0180778 | O12: 0 | P12: -0.102882 | Q12: 0.00808786 | R12: 4.543568e-37 | S12: -8.37944 | T12: 0.681763 | U12: 1.014373e-34 | V12: 4.836476e-10 | W12: 20 | X12: 409 | Y12: Yes | Z12: No | AA12: No | AB12: No | AC12: 2.387834e-31 | AD12: 1.9898617e-32 | AE12: Yes | AF12: Yes | AH12: Global correction covers 2354 disease-probe tests entering SMR Select; it does not correct the preceding region-selection stage. | AI12: No | AJ12: No | AK12: No
A13: eQTLGen + six disease GWAS | B13: iamdgc_lateamd | C13: ENSG00000177888 | D13: 1 | E13: ENSG00000177888 | F13: 197148622 | G13: rs6671696 | H13: 1 | I13: 197083196 | J13: T | K13: C | L13: 0.0889571 | M13: -0.627876 | N13: 0.0336489 | O13: 5.85464e-81 | P13: -0.123122 | Q13: 0.0208335 | R13: 3.425199e-09 | S13: 5.09963 | T13: 0.905155 | U13: 1.760938e-08 | V13: 0.02637387 | W13: 19 | X13: 409 | Y13: Yes | Z13: Yes | AA13: No | AB13: Yes | AC13: 4.1452481e-05 | AD13: 4.5552176e-07 | AE13: Yes | AF13: Yes | AG13: ZBTB41 | AH13: Global correction covers 2354 disease-probe tests entering SMR Select; it does not correct the preceding region-selection stage. | AI13: Yes | AJ13: No | AK13: Yes
A14: eQTLGen + six disease GWAS | B14: iamdgc_lateamd | C14: ENSG00000213047 | D14: 1 | E14: ENSG00000213047 | F14: 197609352 | G14: rs16841912 | H14: 1 | I14: 197702476 | J14: C | K14: G | L14: 0.187117 | M14: 0.0231395 | N14: 0.0212109 | O14: 0.275307 | P14: 0.148702 | Q14: 0.0100149 | R14: 7.167452e-50 | S14: 0.15561 | T14: 0.143025 | U14: 0.2765985 | V14: 1.207851e-14 | W14: 20 | X14: 409 | Y14: No | Z14: No | AA14: No | AB14: No | AC14: 1 | AD14: 0.5996065 | AE14: No | AF14: No | AH14: Global correction covers 2354 disease-probe tests entering SMR Select; it does not correct the preceding region-selection stage. | AI14: No | AJ14: No | AK14: No
A15: eQTLGen + six disease GWAS | B15: iamdgc_lateamd | C15: ENSG00000151414 | D15: 1 | E15: ENSG00000151414 | F15: 198208821 | G15: rs10494768 | H15: 1 | I15: 198252452 | J15: T | K15: G | L15: 0.161554 | M15: -0.0356788 | N15: 0.0249776 | O15: 0.153168 | P15: 0.123583 | Q15: 0.0123826 | R15: 1.857202e-23 | S15: -0.288703 | T15: 0.204171 | U15: 0.1573553 | V15: 0.0182182 | W15: 20 | X15: 409 | Y15: No | Z15: Yes | AA15: No | AB15: No | AC15: 1 | AD15: 0.44255003 | AE15: No | AF15: No | AH15: Global correction covers 2354 disease-probe tests entering SMR Select; it does not correct the preceding region-selection stage. | AI15: No | AJ15: No | AK15: No
A16: eQTLGen + six disease GWAS | B16: iamdgc_lateamd | C16: ENSG00000081237 | D16: 1 | E16: ENSG00000081237 | F16: 198667173 | G16: rs2230606 | H16: 1 | I16: 198676063 | J16: C | K16: A | L16: 0.0143149 | M16: -0.0581011 | N16: 0.0662117 | O16: 0.380212 | P16: 0.28589 | Q16: 0.0366685 | R16: 6.359714e-15 | S16: -0.203229 | T16: 0.233061 | U16: 0.3832087 | V16: 0.01669481 | W16: 19 | X16: 409 | Y16: No | Z16: Yes | AA16: No | AB16: No | AC16: 1 | AD16: 0.70254928 | AE16: No | AF16: No | AH16: Global correction covers 2354 disease-probe tests entering SMR Select; it does not correct the preceding region-selection stage. | AI16: No | AJ16: No | AK16: No
A17: eQTLGen + six disease GWAS | B17: iamdgc_lateamd | C17: ENSG00000163637 | D17: 3 | E17: ENSG00000163637 | F17: 64255347 | G17: rs13072811 | H17: 3 | I17: 64141653 | J17: G | K17: C | L17: 0.391616 | M17: -0.00142085 | N17: 0.0191871 | O17: 0.940969 | P17: -0.070701 | Q17: 0.00812637 | R17: 3.312992e-18 | S17: 0.0200966 | T17: 0.271394 | U17: 0.9409709 | V17: 0.6775782 | W17: 20 | X17: 409 | Y17: No | Z17: Yes | AA17: Yes | AB17: No | AC17: 1 | AD17: 0.97127407 | AE17: No | AF17: No | AH17: Global correction covers 2354 disease-probe tests entering SMR Select; it does not correct the preceding region-selection stage. | AI17: No | AJ17: No | AK17: No
A18: eQTLGen + six disease GWAS | B18: iamdgc_lateamd | C18: ENSG00000224831 | D18: 3 | E18: ENSG00000224831 | F18: 149700530 | G18: rs7644454 | H18: 3 | I18: 149585675 | J18: C | K18: T | L18: 0.270961 | M18: -0.0321417 | N18: 0.0205896 | O18: 0.118509 | P18: -0.218011 | Q18: 0.0225004 | R18: 3.351401e-22 | S18: 0.147432 | T18: 0.0956609 | U18: 0.1232705 | V18: 0.4599537 | W18: 20 | X18: 409 | Y18: No | Z18: Yes | AA18: Yes | AB18: No | AC18: 1 | AD18: 0.38434272 | AE18: No | AF18: No | AH18: Global correction covers 2354 disease-probe tests entering SMR Select; it does not correct the preceding region-selection stage. | AI18: No | AJ18: No | AK18: No
A19: eQTLGen + six disease GWAS | B19: iamdgc_lateamd | C19: ENSG00000070087 | D19: 3 | E19: ENSG00000070087 | F19: 149725633 | G19: rs1563617 | H19: 3 | I19: 149689011 | J19: T | K19: C | L19: 0.376278 | M19: 0.0388187 | N19: 0.0192767 | O19: 0.0440251 | P19: 0.484872 | Q19: 0.00779969 | R19: 0 | S19: 0.0800597 | T19: 0.0397771 | U19: 0.04414546 | V19: 0.6777341 | W19: 20 | X19: 409 | Y19: No | Z19: Yes | AA19: Yes | AB19: No | AC19: 1 | AD19: 0.20496728 | AE19: No | AF19: No | AH19: Global correction covers 2354 disease-probe tests entering SMR Select; it does not correct the preceding region-selection stage. | AI19: No | AJ19: No | AK19: No
A20: eQTLGen + six disease GWAS | B20: iamdgc_lateamd | C20: ENSG00000196428 | D20: 3 | E20: ENSG00000196428 | F20: 150152012 | G20: rs6770424 | H20: 3 | I20: 150174304 | J20: A | K20: G | L20: 0.404908 | M20: 0.044496 | N20: 0.018907 | O20: 0.0185982 | P20: 0.191062 | Q20: 0.00813694 | R20: 6.408483e-122 | S20: 0.232888 | T20: 0.0994532 | U20: 0.01919707 | V20: 0.9768302 | W20: 20 | X20: 409 | Y20: No | Z20: Yes | AA20: Yes | AB20: No | AC20: 1 | AD20: 0.11354247 | AE20: No | AF20: No | AH20: Global correction covers 2354 disease-probe tests entering SMR Select; it does not correct the preceding region-selection stage. | AI20: No | AJ20: No | AK20: No
A21: eQTLGen + six disease GWAS | B21: iamdgc_lateamd | C21: ENSG00000261050 | D21: 3 | E21: ENSG00000261050 | F21: 150182731 | G21: rs1376026 | H21: 3 | I21: 150182592 | J21: A | K21: G | L21: 0.473415 | M21: 0.0123631 | N21: 0.0183577 | O21: 0.50066 | P21: -0.130103 | Q21: 0.0214295 | R21: 1.2696e-09 | S21: -0.0950258 | T21: 0.141967 | U21: 0.503272 | V21: 0.1641607 | W21: 20 | X21: 409 | Y21: No | Z21: Yes | AA21: Yes | AB21: No | AC21: 1 | AD21: 0.79338804 | AE21: No | AF21: No | AH21: Global correction covers 2354 disease-probe tests entering SMR Select; it does not correct the preceding region-selection stage. | AI21: No | AJ21: No | AK21: No
A22: eQTLGen + six disease GWAS | B22: iamdgc_lateamd | C22: ENSG00000144895 | D22: 3 | E22: ENSG00000144895 | F22: 150283247 | G22: rs6440683 | H22: 3 | I22: 150295376 | J22: C | K22: T | L22: 0.143149 | M22: -0.0210036 | N22: 0.0254879 | O22: 0.409904 | P22: -0.527585 | Q22: 0.0109073 | R22: 0 | S22: 0.0398108 | T22: 0.0483175 | U22: 0.4099725 | V22: 0.7714751 | W22: 20 | X22: 409 | Y22: No | Z22: Yes | AA22: Yes | AB22: No | AC22: 1 | AD22: 0.73056417 | AE22: No | AF22: No | AH22: Global correction covers 2354 disease-probe tests entering SMR Select; it does not correct the preceding region-selection stage. | AI22: No | AJ22: No | AK22: No
A23: eQTLGen + six disease GWAS | B23: iamdgc_lateamd | C23: ENSG00000120742 | D23: 3 | E23: ENSG00000120742 | F23: 150290398 | G23: rs13072593 | H23: 3 | I23: 150288489 | J23: G | K23: A | L23: 0.250511 | M23: -0.0298037 | N23: 0.021355 | O23: 0.162825 | P23: 0.134997 | Q23: 0.0091961 | R23: 8.684593e-49 | S23: -0.220773 | T23: 0.158902 | U23: 0.1647214 | V23: 0.6873936 | W23: 20 | X23: 409 | Y23: No | Z23: Yes | AA23: Yes | AB23: No | AC23: 1 | AD23: 0.45618138 | AE23: No | AF23: No | AH23: Global correction covers 2354 disease-probe tests entering SMR Select; it does not correct the preceding region-selection stage. | AI23: No | AJ23: No | AK23: No
A24: eQTLGen + six disease GWAS | B24: iamdgc_lateamd | C24: ENSG00000198843 | D24: 3 | E24: ENSG00000198843 | F24: 150334442 | G24: rs2049227 | H24: 3 | I24: 150346471 | J24: C | K24: T | L24: 0.375256 | M24: 0.00800179 | N24: 0.0189766 | O24: 0.673268 | P24: 0.262263 | Q24: 0.0121272 | R24: 1.022769e-103 | S24: 0.0305106 | T24: 0.0723709 | U24: 0.6733272 | V24: 0.5564388 | W24: 20 | X24: 409 | Y24: No | Z24: Yes | AA24: Yes | AB24: No | AC24: 1 | AD24: 0.87618144 | AE24: No | AF24: No | AH24: Global correction covers 2354 disease-probe tests entering SMR Select; it does not correct the preceding region-selection stage. | AI24: No | AJ24: No | AK24: No
A25: eQTLGen + six disease GWAS | B25: iamdgc_lateamd | C25: ENSG00000240137 | D25: 3 | E25: ENSG00000240137 | F25: 150429642 | G25: rs9814796 | H25: 3 | I25: 150422469 | J25: A | K25: G | L25: 0.349693 | M25: 0.0343296 | N25: 0.0190786 | O25: 0.0719598 | P25: 0.470264 | Q25: 0.0193205 | R25: 7.362393e-131 | S25: 0.0730007 | T25: 0.0406807 | U25: 0.07273651 | V25: 0.8686283 | W25: 20 | X25: 409 | Y25: No | Z25: Yes | AA25: Yes | AB25: No | AC25: 1 | AD25: 0.27775215 | AE25: No | AF25: No | AH25: Global correction covers 2354 disease-probe tests entering SMR Select; it does not correct the preceding region-selection stage. | AI25: No | AJ25: No | AK25: No
... A49: eQTLGen + six disease GWAS | B49: iamdgc_lateamd | C49: ENSG00000204428 | D49: 6 | E49: ENSG00000204428 | F49: 31648139 | G49: rs1144709 | H49: 6 | I49: 31709349 | J49: T | K49: C | L49: 0.239264 | M49: 0.0119335 | N49: 0.0214871 | O49: 0.578635 | P49: -0.521515 | Q49: 0.0135797 | R49: 0 | S49: -0.0228824 | T49: 0.0412056 | U49: 0.5786747 | V49: 7.84078e-25 | W49: 20 | X49: 409 | Y49: No | Z49: No | AA49: No | AB49: No | AC49: 1 | AD49: 0.83876323 | AE49: No | AF49: No | AH49: Global correction covers 2354 disease-probe tests entering SMR Select; it does not correct the preceding region-selection stage. | AI49: No | AJ49: No | AK49: No
A50: eQTLGen + six disease GWAS | B50: iamdgc_lateamd | C50: ENSG00000204427 | D50: 6 | E50: ENSG00000204427 | F50: 31662973 | G50: rs150043706 | H50: 6 | I50: 31578465 | J50: A | K50: G | L50: 0.0184049 | M50: -0.492851 | N50: 0.0749458 | O50: 2.5142e-11 | P50: 0.332273 | Q50: 0.0567639 | R50: 4.810398e-09 | S50: -1.48327 | T50: 0.33924 | U50: 1.229249e-05 | V50: 0.04442672 | W50: 5 | X50: 409 | Y50: Yes | Z50: Yes | AA50: No | AB50: Yes | AC50: 0.028936521 | AD50: 0.00019420484 | AE50: Yes | AF50: Yes | AG50: ABHD16A | AH50: Global correction covers 2354 disease-probe tests entering SMR Select; it does not correct the preceding region-selection stage. | AI50: Yes | AJ50: No | AK50: Yes
A51: eQTLGen + six disease GWAS | B51: iamdgc_lateamd | C51: ENSG00000204421 | D51: 6 | E51: ENSG00000204421 | F51: 31688023 | G51: rs3117572 | H51: 6 | I51: 31717692 | J51: A | K51: G | L51: 0.154397 | M51: -0.0192498 | N51: 0.0238542 | O51: 0.419679 | P51: 0.112507 | Q51: 0.0183901 | R51: 9.487579e-10 | S51: -0.171099 | T51: 0.213861 | U51: 0.4236834 | V51: 0.0009433881 | W51: 20 | X51: 409 | Y51: No | Z51: No | AA51: No | AB51: No | AC51: 1 | AD51: 0.74331014 | AE51: No | AF51: No | AG51: LY6G6C | AH51: Global correction covers 2354 disease-probe tests entering SMR Select; it does not correct the preceding region-selection stage. | AI51: No | AJ51: No | AK51: No
A52: eQTLGen + six disease GWAS | B52: iamdgc_lateamd | C52: ENSG00000213722 | D52: 6 | E52: ENSG00000213722 | F52: 31696604 | G52: rs9267576 | H52: 6 | I52: 31812038 | J52: T | K52: G | L52: 0.108384 | M52: -0.088452 | N52: 0.027073 | O52: 0.00107962 | P52: 0.423021 | Q52: 0.0176535 | R52: 6.861924e-127 | S52: -0.209096 | T52: 0.0645913 | U52: 0.001207024 | V52: 7.291135e-14 | W52: 20 | X52: 409 | Y52: No | Z52: No | AA52: No | AB52: No | AC52: 1 | AD52: 0.011692735 | AE52: No | AF52: Yes | AH52: Global correction covers 2354 disease-probe tests entering SMR Select; it does not correct the preceding region-selection stage. | AI52: No | AJ52: No | AK52: No
A53: eQTLGen + six disease GWAS | B53: iamdgc_lateamd | C53: ENSG00000204410 | D53: 6 | E53: ENSG00000204410 | F53: 31720173 | G53: rs2299851 | H53: 6 | I53: 31718602 | J53: A | K53: G | L53: 0.102249 | M53: -0.254579 | N53: 0.0326438 | O53: 4.87978e-15 | P53: -0.279638 | Q53: 0.030369 | R53: 3.322604e-20 | S53: 0.910388 | T53: 0.152978 | U53: 2.663696e-09 | V53: 1.405405e-06 | W53: 20 | X53: 409 | Y53: Yes | Z53: No | AA53: No | AB53: No | AC53: 6.2703404e-06 | AD53: 8.8314653e-08 | AE53: Yes | AF53: Yes | AH53: Global correction covers 2354 disease-probe tests entering SMR Select; it does not correct the preceding region-selection stage. | AI53: No | AJ53: No | AK53: No
A54: eQTLGen + six disease GWAS | B54: iamdgc_lateamd | C54: ENSG00000204396 | D54: 6 | E54: ENSG00000204396 | F54: 31739237 | G54: rs28745895 | H54: 6 | I54: 31709969 | J54: A | K54: C | L54: 0.0531697 | M54: -0.157552 | N54: 0.0569449 | O54: 0.00558599 | P54: -0.516843 | Q54: 0.0406918 | R54: 5.808152e-37 | S54: 0.304835 | T54: 0.112762 | U54: 0.006864418 | V54: 1.880404e-09 | W54: 20 | X54: 409 | Y54: No | Z54: No | AA54: No | AB54: No | AC54: 1 | AD54: 0.051461274 | AE54: No | AF54: No | AH54: Global correction covers 2354 disease-probe tests entering SMR Select; it does not correct the preceding region-selection stage. | AI54: No | AJ54: No | AK54: No
